[2024-03-20T18:41:34.621+0000] {taskinstance.py:1979} INFO - Dependencies all met for dep_context=non-requeueable deps ti=<TaskInstance: dag_sensor_minio_s3_v1.sensing_s3 manual__2024-03-20T18:41:33.860203+00:00 [queued]>
[2024-03-20T18:41:34.625+0000] {taskinstance.py:1979} INFO - Dependencies all met for dep_context=requeueable deps ti=<TaskInstance: dag_sensor_minio_s3_v1.sensing_s3 manual__2024-03-20T18:41:33.860203+00:00 [queued]>
[2024-03-20T18:41:34.625+0000] {taskinstance.py:2193} INFO - Starting attempt 1 of 1
[2024-03-20T18:41:34.638+0000] {taskinstance.py:2217} INFO - Executing <Task(S3KeySensor): sensing_s3> on 2024-03-20 18:41:33.860203+00:00
[2024-03-20T18:41:34.647+0000] {standard_task_runner.py:60} INFO - Started process 3572 to run task
[2024-03-20T18:41:34.656+0000] {standard_task_runner.py:87} INFO - Running: ['***', 'tasks', 'run', 'dag_sensor_minio_s3_v1', 'sensing_s3', 'manual__2024-03-20T18:41:33.860203+00:00', '--job-id', '6', '--raw', '--subdir', 'DAGS_FOLDER/dag_with_minio_s3_SensorOperator.py', '--cfg-path', '/tmp/tmpjpsw1_ox']
[2024-03-20T18:41:34.661+0000] {standard_task_runner.py:88} INFO - Job 6: Subtask sensing_s3
[2024-03-20T18:41:34.713+0000] {task_command.py:423} INFO - Running <TaskInstance: dag_sensor_minio_s3_v1.sensing_s3 manual__2024-03-20T18:41:33.860203+00:00 [running]> on host c1f7f51b1f08
[2024-03-20T18:41:34.781+0000] {taskinstance.py:2513} INFO - Exporting env vars: AIRFLOW_CTX_DAG_OWNER='Hitesh' AIRFLOW_CTX_DAG_ID='dag_sensor_minio_s3_v1' AIRFLOW_CTX_TASK_ID='sensing_s3' AIRFLOW_CTX_EXECUTION_DATE='2024-03-20T18:41:33.860203+00:00' AIRFLOW_CTX_TRY_NUMBER='1' AIRFLOW_CTX_DAG_RUN_ID='manual__2024-03-20T18:41:33.860203+00:00'
[2024-03-20T18:41:34.781+0000] {s3.py:110} INFO - Poking for key : s3://***/data.csv
[2024-03-20T18:41:34.788+0000] {base.py:83} INFO - Using connection ID 'minio_s3' for task execution.
[2024-03-20T18:41:34.793+0000] {logging_mixin.py:188} WARNING - <string>:9 AirflowProviderDeprecationWarning: extra['host'] is deprecated and will be removed in a future release. Please set extra['endpoint_url'] instead
[2024-03-20T18:41:35.128+0000] {taskinstance.py:2731} ERROR - Task failed with exception
Traceback (most recent call last):
  File "/home/airflow/.local/lib/python3.8/site-packages/airflow/models/taskinstance.py", line 444, in _execute_task
    result = _execute_callable(context=context, **execute_callable_kwargs)
  File "/home/airflow/.local/lib/python3.8/site-packages/airflow/models/taskinstance.py", line 414, in _execute_callable
    return execute_callable(context=context, **execute_callable_kwargs)
  File "/home/airflow/.local/lib/python3.8/site-packages/airflow/providers/amazon/aws/sensors/s3.py", line 153, in execute
    super().execute(context)
  File "/home/airflow/.local/lib/python3.8/site-packages/airflow/sensors/base.py", line 265, in execute
    raise e
  File "/home/airflow/.local/lib/python3.8/site-packages/airflow/sensors/base.py", line 247, in execute
    poke_return = self.poke(context)
  File "/home/airflow/.local/lib/python3.8/site-packages/airflow/providers/amazon/aws/sensors/s3.py", line 146, in poke
    return self._check_key(self.bucket_key)
  File "/home/airflow/.local/lib/python3.8/site-packages/airflow/providers/amazon/aws/sensors/s3.py", line 134, in _check_key
    obj = self.hook.head_object(key, bucket_name)
  File "/home/airflow/.local/lib/python3.8/site-packages/airflow/providers/amazon/aws/hooks/s3.py", line 137, in wrapper
    return func(*bound_args.args, **bound_args.kwargs)
  File "/home/airflow/.local/lib/python3.8/site-packages/airflow/providers/amazon/aws/hooks/s3.py", line 91, in wrapper
    return func(*bound_args.args, **bound_args.kwargs)
  File "/home/airflow/.local/lib/python3.8/site-packages/airflow/providers/amazon/aws/hooks/s3.py", line 901, in head_object
    return self.get_conn().head_object(Bucket=bucket_name, Key=key)
  File "/home/airflow/.local/lib/python3.8/site-packages/botocore/client.py", line 553, in _api_call
    return self._make_api_call(operation_name, kwargs)
  File "/home/airflow/.local/lib/python3.8/site-packages/botocore/client.py", line 989, in _make_api_call
    http, parsed_response = self._make_request(
  File "/home/airflow/.local/lib/python3.8/site-packages/botocore/client.py", line 1015, in _make_request
    return self._endpoint.make_request(operation_model, request_dict)
  File "/home/airflow/.local/lib/python3.8/site-packages/botocore/endpoint.py", line 119, in make_request
    return self._send_request(request_dict, operation_model)
  File "/home/airflow/.local/lib/python3.8/site-packages/botocore/endpoint.py", line 198, in _send_request
    request = self.create_request(request_dict, operation_model)
  File "/home/airflow/.local/lib/python3.8/site-packages/botocore/endpoint.py", line 134, in create_request
    self._event_emitter.emit(
  File "/home/airflow/.local/lib/python3.8/site-packages/botocore/hooks.py", line 412, in emit
    return self._emitter.emit(aliased_event_name, **kwargs)
  File "/home/airflow/.local/lib/python3.8/site-packages/botocore/hooks.py", line 256, in emit
    return self._emit(event_name, kwargs)
  File "/home/airflow/.local/lib/python3.8/site-packages/botocore/hooks.py", line 239, in _emit
    response = handler(**kwargs)
  File "/home/airflow/.local/lib/python3.8/site-packages/botocore/signers.py", line 105, in handler
    return self.sign(operation_name, request)
  File "/home/airflow/.local/lib/python3.8/site-packages/botocore/signers.py", line 195, in sign
    auth.add_auth(request)
  File "/home/airflow/.local/lib/python3.8/site-packages/botocore/auth.py", line 432, in add_auth
    self._inject_signature_to_request(request, signature)
  File "/home/airflow/.local/lib/python3.8/site-packages/botocore/auth.py", line 435, in _inject_signature_to_request
    auth_str = ['AWS4-HMAC-SHA256 Credential=%s' % self.scope(request)]
  File "/home/airflow/.local/lib/python3.8/site-packages/botocore/auth.py", line 384, in scope
    return '/'.join(scope)
TypeError: sequence item 0: expected str instance, NoneType found
[2024-03-20T18:41:35.138+0000] {taskinstance.py:1149} INFO - Marking task as FAILED. dag_id=dag_sensor_minio_s3_v1, task_id=sensing_s3, execution_date=20240320T184133, start_date=20240320T184134, end_date=20240320T184135
[2024-03-20T18:41:35.147+0000] {standard_task_runner.py:107} ERROR - Failed to execute job 6 for task sensing_s3 (sequence item 0: expected str instance, NoneType found; 3572)
[2024-03-20T18:41:35.169+0000] {local_task_job_runner.py:234} INFO - Task exited with return code 1
[2024-03-20T18:41:35.189+0000] {taskinstance.py:3312} INFO - 0 downstream tasks scheduled from follow-on schedule check
