[2024-03-20T04:25:12.916+0000] {taskinstance.py:1979} INFO - Dependencies all met for dep_context=non-requeueable deps ti=<TaskInstance: dag_with_cron_expression_v1.first_task manual__2024-03-20T04:23:11.138130+00:00 [queued]>
[2024-03-20T04:25:12.919+0000] {taskinstance.py:1979} INFO - Dependencies all met for dep_context=requeueable deps ti=<TaskInstance: dag_with_cron_expression_v1.first_task manual__2024-03-20T04:23:11.138130+00:00 [queued]>
[2024-03-20T04:25:12.919+0000] {taskinstance.py:2193} INFO - Starting attempt 2 of 6
[2024-03-20T04:25:12.924+0000] {taskinstance.py:2217} INFO - Executing <Task(BashOperator): first_task> on 2024-03-20 04:23:11.138130+00:00
[2024-03-20T04:25:12.926+0000] {standard_task_runner.py:60} INFO - Started process 10951 to run task
[2024-03-20T04:25:12.928+0000] {standard_task_runner.py:87} INFO - Running: ['***', 'tasks', 'run', 'dag_with_cron_expression_v1', 'first_task', 'manual__2024-03-20T04:23:11.138130+00:00', '--job-id', '53', '--raw', '--subdir', 'DAGS_FOLDER/dag_with_cron_expression.py', '--cfg-path', '/tmp/tmpq9ndrite']
[2024-03-20T04:25:12.929+0000] {standard_task_runner.py:88} INFO - Job 53: Subtask first_task
[2024-03-20T04:25:12.945+0000] {task_command.py:423} INFO - Running <TaskInstance: dag_with_cron_expression_v1.first_task manual__2024-03-20T04:23:11.138130+00:00 [running]> on host be400aaaf05d
[2024-03-20T04:25:12.971+0000] {taskinstance.py:2513} INFO - Exporting env vars: AIRFLOW_CTX_DAG_OWNER='Hitesh' AIRFLOW_CTX_DAG_ID='dag_with_cron_expression_v1' AIRFLOW_CTX_TASK_ID='first_task' AIRFLOW_CTX_EXECUTION_DATE='2024-03-20T04:23:11.138130+00:00' AIRFLOW_CTX_TRY_NUMBER='2' AIRFLOW_CTX_DAG_RUN_ID='manual__2024-03-20T04:23:11.138130+00:00'
[2024-03-20T04:25:12.972+0000] {subprocess.py:63} INFO - Tmp dir root location: /tmp
[2024-03-20T04:25:12.973+0000] {subprocess.py:75} INFO - Running command: ['/usr/bin/bash', '-c', 'Hello world!']
[2024-03-20T04:25:12.976+0000] {subprocess.py:86} INFO - Output:
[2024-03-20T04:25:12.977+0000] {subprocess.py:93} INFO - /usr/bin/bash: line 1: Hello: command not found
[2024-03-20T04:25:12.978+0000] {subprocess.py:97} INFO - Command exited with return code 127
[2024-03-20T04:25:12.981+0000] {taskinstance.py:2731} ERROR - Task failed with exception
Traceback (most recent call last):
  File "/home/airflow/.local/lib/python3.8/site-packages/airflow/models/taskinstance.py", line 444, in _execute_task
    result = _execute_callable(context=context, **execute_callable_kwargs)
  File "/home/airflow/.local/lib/python3.8/site-packages/airflow/models/taskinstance.py", line 414, in _execute_callable
    return execute_callable(context=context, **execute_callable_kwargs)
  File "/home/airflow/.local/lib/python3.8/site-packages/airflow/operators/bash.py", line 212, in execute
    raise AirflowException(
airflow.exceptions.AirflowException: Bash command failed. The command returned a non-zero exit code 127.
[2024-03-20T04:25:12.983+0000] {taskinstance.py:1149} INFO - Marking task as UP_FOR_RETRY. dag_id=dag_with_cron_expression_v1, task_id=first_task, execution_date=20240320T042311, start_date=20240320T042512, end_date=20240320T042512
[2024-03-20T04:25:12.987+0000] {standard_task_runner.py:107} ERROR - Failed to execute job 53 for task first_task (Bash command failed. The command returned a non-zero exit code 127.; 10951)
[2024-03-20T04:25:13.034+0000] {local_task_job_runner.py:234} INFO - Task exited with return code 1
[2024-03-20T04:25:13.041+0000] {taskinstance.py:3312} INFO - 0 downstream tasks scheduled from follow-on schedule check
