[2024-03-19T21:35:50.083+0000] {taskinstance.py:1979} INFO - Dependencies all met for dep_context=non-requeueable deps ti=<TaskInstance: dag_with_python_operator_v5.greet manual__2024-03-19T21:35:48.544032+00:00 [queued]>
[2024-03-19T21:35:50.087+0000] {taskinstance.py:1979} INFO - Dependencies all met for dep_context=requeueable deps ti=<TaskInstance: dag_with_python_operator_v5.greet manual__2024-03-19T21:35:48.544032+00:00 [queued]>
[2024-03-19T21:35:50.087+0000] {taskinstance.py:2193} INFO - Starting attempt 1 of 6
[2024-03-19T21:35:50.092+0000] {taskinstance.py:2217} INFO - Executing <Task(PythonOperator): greet> on 2024-03-19 21:35:48.544032+00:00
[2024-03-19T21:35:50.094+0000] {standard_task_runner.py:60} INFO - Started process 3931 to run task
[2024-03-19T21:35:50.095+0000] {standard_task_runner.py:87} INFO - Running: ['***', 'tasks', 'run', 'dag_with_python_operator_v5', 'greet', 'manual__2024-03-19T21:35:48.544032+00:00', '--job-id', '18', '--raw', '--subdir', 'DAGS_FOLDER/dag_with_python_operator.py', '--cfg-path', '/tmp/tmpor05xjrt']
[2024-03-19T21:35:50.096+0000] {standard_task_runner.py:88} INFO - Job 18: Subtask greet
[2024-03-19T21:35:50.112+0000] {task_command.py:423} INFO - Running <TaskInstance: dag_with_python_operator_v5.greet manual__2024-03-19T21:35:48.544032+00:00 [running]> on host be400aaaf05d
[2024-03-19T21:35:50.137+0000] {taskinstance.py:2513} INFO - Exporting env vars: AIRFLOW_CTX_DAG_OWNER='Hitesh' AIRFLOW_CTX_DAG_ID='dag_with_python_operator_v5' AIRFLOW_CTX_TASK_ID='greet' AIRFLOW_CTX_EXECUTION_DATE='2024-03-19T21:35:48.544032+00:00' AIRFLOW_CTX_TRY_NUMBER='1' AIRFLOW_CTX_DAG_RUN_ID='manual__2024-03-19T21:35:48.544032+00:00'
[2024-03-19T21:35:50.138+0000] {taskinstance.py:2731} ERROR - Task failed with exception
Traceback (most recent call last):
  File "/home/airflow/.local/lib/python3.8/site-packages/airflow/models/taskinstance.py", line 444, in _execute_task
    result = _execute_callable(context=context, **execute_callable_kwargs)
  File "/home/airflow/.local/lib/python3.8/site-packages/airflow/models/taskinstance.py", line 414, in _execute_callable
    return execute_callable(context=context, **execute_callable_kwargs)
  File "/home/airflow/.local/lib/python3.8/site-packages/airflow/operators/python.py", line 200, in execute
    return_value = self.execute_callable()
  File "/home/airflow/.local/lib/python3.8/site-packages/airflow/operators/python.py", line 217, in execute_callable
    return self.python_callable(*self.op_args, **self.op_kwargs)
TypeError: greet() missing 1 required positional argument: 'age'
[2024-03-19T21:35:50.140+0000] {taskinstance.py:1149} INFO - Marking task as UP_FOR_RETRY. dag_id=dag_with_python_operator_v5, task_id=greet, execution_date=20240319T213548, start_date=20240319T213550, end_date=20240319T213550
[2024-03-19T21:35:50.144+0000] {standard_task_runner.py:107} ERROR - Failed to execute job 18 for task greet (greet() missing 1 required positional argument: 'age'; 3931)
[2024-03-19T21:35:50.153+0000] {local_task_job_runner.py:234} INFO - Task exited with return code 1
[2024-03-19T21:35:50.160+0000] {taskinstance.py:3312} INFO - 0 downstream tasks scheduled from follow-on schedule check
